[?] 379130 bytes of extra data after image end (IEND), offset = 0x4286c
ERROR:stegoveritas.helpers:[31m[31mnot supported for mode RGBA[0m[0m
ERROR:stegoveritas.helpers:[31m[31m
"""
Traceback (most recent call last):
  File "/usr/lib/python3.11/multiprocessing/pool.py", line 125, in worker
    result = (True, func(*args, **kwds))
                    ^^^^^^^^^^^^^^^^^^^
  File "/usr/local/lib/python3.11/dist-packages/stegoveritas/modules/image/analysis/filters.py", line 40, in run_image_op
    raise e
  File "/usr/local/lib/python3.11/dist-packages/stegoveritas/modules/image/analysis/filters.py", line 34, in run_image_op
    img = op(image.file)
          ^^^^^^^^^^^^^^
  File "/usr/lib/python3/dist-packages/PIL/ImageOps.py", line 162, in autocontrast
    return _lut(image, lut)
           ^^^^^^^^^^^^^^^^
  File "/usr/lib/python3/dist-packages/PIL/ImageOps.py", line 62, in _lut
    raise OSError(msg)
OSError: not supported for mode RGBA
"""[0m[0m
ERROR:stegoveritas.helpers:[31m[31mnot supported for mode RGBA[0m[0m
ERROR:stegoveritas.helpers:[31m[31m
"""
Traceback (most recent call last):
  File "/usr/lib/python3.11/multiprocessing/pool.py", line 125, in worker
    result = (True, func(*args, **kwds))
                    ^^^^^^^^^^^^^^^^^^^
  File "/usr/local/lib/python3.11/dist-packages/stegoveritas/modules/image/analysis/filters.py", line 40, in run_image_op
    raise e
  File "/usr/local/lib/python3.11/dist-packages/stegoveritas/modules/image/analysis/filters.py", line 34, in run_image_op
    img = op(image.file)
          ^^^^^^^^^^^^^^
  File "/usr/lib/python3/dist-packages/PIL/ImageOps.py", line 478, in equalize
    return _lut(image, lut)
           ^^^^^^^^^^^^^^^^
  File "/usr/lib/python3/dist-packages/PIL/ImageOps.py", line 62, in _lut
    raise OSError(msg)
OSError: not supported for mode RGBA
"""[0m[0m
ERROR:stegoveritas.helpers:[31m[31mnot supported for mode RGBA[0m[0m
ERROR:stegoveritas.helpers:[31m[31m
"""
Traceback (most recent call last):
  File "/usr/lib/python3.11/multiprocessing/pool.py", line 125, in worker
    result = (True, func(*args, **kwds))
                    ^^^^^^^^^^^^^^^^^^^
  File "/usr/local/lib/python3.11/dist-packages/stegoveritas/modules/image/analysis/filters.py", line 40, in run_image_op
    raise e
  File "/usr/local/lib/python3.11/dist-packages/stegoveritas/modules/image/analysis/filters.py", line 34, in run_image_op
    img = op(image.file)
          ^^^^^^^^^^^^^^
  File "/usr/lib/python3/dist-packages/PIL/ImageOps.py", line 630, in invert
    return image.point(lut) if image.mode == "1" else _lut(image, lut)
                                                      ^^^^^^^^^^^^^^^^
  File "/usr/lib/python3/dist-packages/PIL/ImageOps.py", line 62, in _lut
    raise OSError(msg)
OSError: not supported for mode RGBA
"""[0m[0m
ERROR:stegoveritas.helpers:[31m[31mnot supported for mode RGBA[0m[0m
ERROR:stegoveritas.helpers:[31m[31m
"""
Traceback (most recent call last):
  File "/usr/lib/python3.11/multiprocessing/pool.py", line 125, in worker
    result = (True, func(*args, **kwds))
                    ^^^^^^^^^^^^^^^^^^^
  File "/usr/local/lib/python3.11/dist-packages/stegoveritas/modules/image/analysis/filters.py", line 40, in run_image_op
    raise e
  File "/usr/local/lib/python3.11/dist-packages/stegoveritas/modules/image/analysis/filters.py", line 34, in run_image_op
    img = op(image.file)
          ^^^^^^^^^^^^^^
  File "/usr/lib/python3/dist-packages/PIL/ImageOps.py", line 670, in solarize
    return _lut(image, lut)
           ^^^^^^^^^^^^^^^^
  File "/usr/lib/python3/dist-packages/PIL/ImageOps.py", line 62, in _lut
    raise OSError(msg)
OSError: not supported for mode RGBA
"""[0m[0m
Traceback (most recent call last):
  File "/usr/lib/python3.11/shutil.py", line 853, in move
    os.rename(src, real_dst)
FileNotFoundError: [Errno 2] No such file or directory: '/tmp/tmpnye5y6og/_scanme.extracted/4286C.zip' -> 'results_dolls.png/keepers/4286C.zip'

During handling of the above exception, another exception occurred:

Traceback (most recent call last):
  File "/usr/local/bin/stegoveritas", line 8, in <module>
    sys.exit(main())
             ^^^^^^
  File "/usr/local/lib/python3.11/dist-packages/stegoveritas/stegoveritas.py", line 270, in main
    veritas.run()
  File "/usr/local/lib/python3.11/dist-packages/stegoveritas/stegoveritas.py", line 53, in run
    module.run()
  File "/usr/local/lib/python3.11/dist-packages/stegoveritas/modules/__init__.py", line 31, in run
    module.run(self)
  File "/usr/local/lib/python3.11/dist-packages/stegoveritas/modules/multi/analysis/carve.py", line 29, in run
    multi.veritas.test_output(f.read())
  File "/usr/local/lib/python3.11/dist-packages/stegoveritas/stegoveritas.py", line 148, in test_output
    shutil.move(keeper, keeper_dst)
  File "/usr/lib/python3.11/shutil.py", line 873, in move
    copy_function(src, real_dst)
  File "/usr/lib/python3.11/shutil.py", line 448, in copy2
    copyfile(src, dst, follow_symlinks=follow_symlinks)
  File "/usr/lib/python3.11/shutil.py", line 258, in copyfile
    with open(dst, 'wb') as fdst:
         ^^^^^^^^^^^^^^^
FileNotFoundError: [Errno 2] No such file or directory: 'results_dolls.png/keepers/4286C.zip'
